<?xml version="1.0" ?>
<!-- =================================================================================== -->
<!-- |    This document was autogenerated by xacro from custom_arm.xacro               | -->
<!-- |    EDITING THIS FILE BY HAND IS NOT RECOMMENDED                                 | -->
<!-- =================================================================================== -->
<robot name="custom_arm">
  <link name="world"/>
  <joint name="base_link_joint" type="fixed">
    <origin rpy="0 0 0" xyz="0 0 0"/>
    <parent link="world"/>
    <child link="base_link"/>
  </joint>
  <link name="base_link">
    <visual>
      <geometry>
        <mesh filename="package://custom_arm_description/meshes/DAE/base/base.dae"/>
      </geometry>
    </visual>
    <collision>
      <geometry>
        <mesh filename="package://custom_arm_description/meshes/STL/base/base.stl"/>
      </geometry>
    </collision>
    <inertial>
      <origin xyz="0 0 0"/>
      <mass value="27"/>
      <inertia ixx="2.91" ixy="0" ixz="0" iyy="18.03" iyz="0" izz="20.95"/>
    </inertial>
    <surface>
      <friction>
        <ode>
          <mu>0.8</mu>
          <mu2>0.8</mu2>
          <kp>1e15</kp>
          <kd>1e13</kd>
        </ode>
      </friction>
      <bounce>
        <restitution_coefficient>0.01</restitution_coefficient>
        <threshold>10</threshold>
      </bounce>
      <contact>
        <ode>
          <max_vel>0.01</max_vel>
          <minDepth>0</minDepth>
          <contact_surface_layer>0</contact_surface_layer>
        </ode>
      </contact>
    </surface>
  </link>
  <joint name="soulder_joint" type="revolute">
    <origin rpy="0 0 0" xyz="0.0 0.0 0.05"/>
    <parent link="base_link"/>
    <child link="shoulder_link"/>
    <limit effort="100" lower="-3.14" upper="3.14" velocity="100"/>
    <dynamics damping="0.1" friction="0.1"/>
    <axis xyz="0 0 1"/>
  </joint>
  <link name="shoulder_link">
    <visual>
      <geometry>
        <mesh filename="package://custom_arm_description/meshes/DAE/shoulder/shoulder.dae"/>
      </geometry>
    </visual>
    <collision>
      <geometry>
        <mesh filename="package://custom_arm_description/meshes/STL/shoulder/shoulder.stl"/>
      </geometry>
    </collision>
    <inertial>
      <origin xyz="0.0000223482 0.0000414609 0.0066287000"/>
      <mass value="0.480879"/>
      <inertia ixx="0.222" ixy="0" ixz="0" iyy="0.395" iyz="0" izz="0.222"/>
    </inertial>
    <surface>
      <friction>
        <ode>
          <mu1>1.2</mu1>
          <mu2>1.2</mu2>
          <kp>1e15</kp>
          <kd>1e13</kd>
        </ode>
      </friction>
      <bounce>
        <restitution_coefficient>0.01</restitution_coefficient>
        <threshold>0</threshold>
      </bounce>
      <contact>
        <ode>
          <max_vel>10</max_vel>
        </ode>
      </contact>
    </surface>
  </link>
  <joint name="upper_arm_joint" type="revolute">
    <origin rpy="0 0 0" xyz="0.0 0.0 0.021"/>
    <parent link="shoulder_link"/>
    <child link="upper_arm_link"/>
    <limit effort="100" lower="-3.14" upper="3.14" velocity="100"/>
    <dynamics damping="0.1" friction="0.1"/>
    <axis xyz="0 1 0"/>
  </joint>
  <link name="upper_arm_link">
    <visual>
      <geometry>
        <mesh filename="package://custom_arm_description/meshes/DAE/upper_arm/upper_arm.dae"/>
      </geometry>
    </visual>
    <collision>
      <geometry>
        <mesh filename="package://custom_arm_description/meshes/STL/upper_arm/upper_arm.stl"/>
      </geometry>
    </collision>
    <inertial>
      <origin xyz="0.0 0.0 0.0"/>
      <mass value="0.298"/>
      <inertia ixx="0.002176" ixy="-0.0000030658" ixz="0.0" iyy="0.00005757" iyz="0.0" izz="0.002186"/>
    </inertial>
    <surface>
      <friction>
        <ode>
          <mu1>1.2</mu1>
          <mu2>1.2</mu2>
          <kp>1e15</kp>
          <kd>1e13</kd>
        </ode>
      </friction>
      <bounce>
        <restitution_coefficient>0.01</restitution_coefficient>
        <threshold>0</threshold>
      </bounce>
      <contact>
        <ode>
          <max_vel>10</max_vel>
        </ode>
      </contact>
    </surface>
  </link>
  <joint name="elbow_joint" type="revolute">
    <origin rpy="0 0 0" xyz="0.0 0.0 0.0685"/>
    <parent link="upper_arm_link"/>
    <child link="elbow_link"/>
    <limit effort="100" lower="-3.14" upper="3.14" velocity="100"/>
    <dynamics damping="0.1" friction="0.1"/>
    <axis xyz="1 0 0"/>
  </joint>
  <link name="elbow_link">
    <visual>
      <geometry>
        <mesh filename="package://custom_arm_description/meshes/DAE/elbow/elbow.dae"/>
      </geometry>
    </visual>
    <collision>
      <geometry>
        <mesh filename="package://custom_arm_description/meshes/STL/elbow/elbow.stl"/>
      </geometry>
    </collision>
    <inertial>
      <origin xyz="0.1079630000 0.0001158760 0"/>
      <mass value="0.234589"/>
      <inertia ixx="0.00003971" ixy="0.0000023528" ixz="0.0" iyy="0.0008878" iyz="0.0" izz="0.000888"/>
    </inertial>
    <surface>
      <friction>
        <ode>
          <mu1>1.2</mu1>
          <mu2>1.2</mu2>
          <kp>1e15</kp>
          <kd>1e13</kd>
        </ode>
      </friction>
      <bounce>
        <restitution_coefficient>0.01</restitution_coefficient>
        <threshold>0</threshold>
      </bounce>
      <contact>
        <ode>
          <max_vel>10</max_vel>
        </ode>
      </contact>
    </surface>
  </link>
  <joint name="lower_arm_joint" type="revolute">
    <origin rpy="0 -1.57079637 0" xyz="0.0 0.0 0.078"/>
    <parent link="elbow_link"/>
    <child link="lower_arm_link"/>
    <limit effort="100" lower="-3.14" upper="3.14" velocity="100"/>
    <dynamics damping="0.1" friction="0.1"/>
    <axis xyz="0 1 0"/>
  </joint>
  <link name="lower_arm_link">
    <visual>
      <geometry>
        <mesh filename="package://custom_arm_description/meshes/DAE/lower_arm/lower_arm.dae"/>
      </geometry>
    </visual>
    <collision>
      <geometry>
        <mesh filename="package://custom_arm_description/meshes/STL/lower_arm/lower_arm.stl"/>
      </geometry>
    </collision>
    <inertial>
      <origin xyz="0.0374395000 0.0052225200 0"/>
      <mass value="0.220991"/>
      <inertia ixx="0.00006369" ixy="-0.00002292" ixz="0.0" iyy="0.0001677" iyz="0.0" izz="0.0001834"/>
    </inertial>
    <surface>
      <friction>
        <ode>
          <mu1>1.2</mu1>
          <mu2>1.2</mu2>
          <kp>1e15</kp>
          <kd>1e13</kd>
        </ode>
      </friction>
      <bounce>
        <restitution_coefficient>0.01</restitution_coefficient>
        <threshold>0</threshold>
      </bounce>
      <contact>
        <ode>
          <max_vel>10</max_vel>
        </ode>
      </contact>
    </surface>
  </link>
  <joint name="wrist_joint" type="revolute">
    <origin rpy="0 -1.57079637 0" xyz="0.0 0.0 0.083"/>
    <parent link="lower_arm_link"/>
    <child link="wrist_link"/>
    <limit effort="100" lower="-3.14" upper="3.14" velocity="100"/>
    <dynamics damping="0.1" friction="0.1"/>
    <axis xyz="0 1 0"/>
  </joint>
  <link name="wrist_link">
    <visual>
      <geometry>
        <mesh filename="package://custom_arm_description/meshes/DAE/wrist/wrist.dae"/>
      </geometry>
    </visual>
    <collision>
      <geometry>
        <mesh filename="package://custom_arm_description/meshes/STL/wrist/wrist.stl"/>
      </geometry>
    </collision>
    <inertial>
      <origin xyz="0.0 0.0 0.0"/>
      <mass value="0.085"/>
      <inertia ixx="0.00003082" ixy="0.0000000191" ixz="0.0000000023" iyy="0.00002822" iyz="0.0000025481" izz="0.00003152"/>
    </inertial>
    <surface>
      <friction>
        <ode>
          <mu1>1.2</mu1>
          <mu2>1.2</mu2>
          <kp>1e15</kp>
          <kd>1e13</kd>
        </ode>
      </friction>
      <bounce>
        <restitution_coefficient>0.01</restitution_coefficient>
        <threshold>0</threshold>
      </bounce>
      <contact>
        <ode>
          <max_vel>10</max_vel>
        </ode>
      </contact>
    </surface>
  </link>
  <joint name="gripper_joint" type="revolute">
    <origin rpy="0 0 0" xyz="0.0 0.0 0.122"/>
    <parent link="wrist_link"/>
    <child link="gripper_link"/>
    <limit effort="100" lower="-3.14" upper="3.14" velocity="100"/>
    <dynamics damping="0.1" friction="0.1"/>
    <axis xyz="0 0 1"/>
  </joint>
  <link name="gripper_link">
    <visual>
      <geometry>
        <mesh filename="package://custom_arm_description/meshes/DAE/gripper/gripper.dae"/>
      </geometry>
    </visual>
    <collision>
      <geometry>
        <mesh filename="package://custom_arm_description/meshes/STL/gripper/gripper.stl"/>
      </geometry>
    </collision>
    <inertial>
      <origin xyz="0.0 0.0 0.0"/>
      <mass value="0.25"/>
      <inertia ixx="0.00002537" ixy="0.0" ixz="0.0" iyy="0.00001836" iyz="0.000000434" izz="0.00001674"/>
    </inertial>
    <surface>
      <friction>
        <ode>
          <mu1>1.2</mu1>
          <mu2>1.2</mu2>
          <kp>1e15</kp>
          <kd>1e13</kd>
        </ode>
      </friction>
      <bounce>
        <restitution_coefficient>0.01</restitution_coefficient>
        <threshold>0</threshold>
      </bounce>
      <contact>
        <ode>
          <max_vel>10</max_vel>
        </ode>
      </contact>
    </surface>
  </link>
  <joint name="finger_joint" type="revolute">
    <origin rpy="-0.52359879 0 0" xyz="0.0 0.01475 -0.037"/>
    <parent link="gripper_link"/>
    <child link="finger_link"/>
    <limit effort="100" lower="-1.57" upper="1.57" velocity="100"/>
    <dynamics damping="0.005" friction="0.039"/>
    <axis xyz="1 0 0"/>
  </joint>
  <link name="finger_link">
    <visual>
      <geometry>
        <mesh filename="package://custom_arm_description/meshes/DAE/finger/finger.dae"/>
      </geometry>
    </visual>
    <collision>
      <geometry>
        <mesh filename="package://custom_arm_description/meshes/STL/finger/finger.stl"/>
      </geometry>
    </collision>
    <inertial>
      <origin xyz="0.0 0.0 0.0"/>
      <mass value="0.016"/>
      <inertia ixx="0.000004731" ixy="-0.000000456" ixz="0.0" iyy="-0.000000456" iyz="0.0" izz="0.0000037467"/>
    </inertial>
    <surface>
      <friction>
        <ode>
          <mu1>1.2</mu1>
          <mu2>1.2</mu2>
          <kp>1e15</kp>
          <kd>1e13</kd>
        </ode>
      </friction>
      <bounce>
        <restitution_coefficient>0.01</restitution_coefficient>
        <threshold>0</threshold>
      </bounce>
      <contact>
        <ode>
          <max_vel>10</max_vel>
        </ode>
      </contact>
    </surface>
  </link>
</robot>
